Workbook
Name _Hlk504127682: QCF!#REF!
Name _Hlk57986371: QCF!#REF!

Sheet Data INPUT
A1: New IFS SPEC Sheet 04/07/2026 V1
A2: Quote REF | AA2: Width Details | AB2: No. Of Panels | AC2: No. of Motors
A3: Project Name | G3: TYPE A | I3: TYPE B | K3: TYPE C | M3: TYPE D | AA3: up to 5.5m | AB3: CSV x 1 | AC3: =_xlfn.NUMBERVALUE(_xlfn.TEXTAFTER(AB3, " ", -1), ".", ",") -> 1
A4: Customer | AA4: 5.5m to 11m | AB4: CSV x 2 | AC4: =_xlfn.NUMBERVALUE(_xlfn.TEXTAFTER(AB4, " ", -1), ".", ",") -> 2
A5: Contact Name | AA5: 12m to 17 | AB5: CSV x 3 | AC5: =_xlfn.NUMBERVALUE(_xlfn.TEXTAFTER(AB5, " ", -1), ".", ",") -> 3
A6: Contact Number | AA6: 17m to 22.5 | AB6: CSV x 4 | AC6: =_xlfn.NUMBERVALUE(_xlfn.TEXTAFTER(AB6, " ", -1), ".", ",") -> 4
A7: Address | AA7: 22.5 to 28m | AB7: CSV x 5 | AC7: =_xlfn.NUMBERVALUE(_xlfn.TEXTAFTER(AB7, " ", -1), ".", ",") -> 5
AA8: up to 30m | AB8: CSV x 6 | AC8: =_xlfn.NUMBERVALUE(_xlfn.TEXTAFTER(AB8, " ", -1), ".", ",") -> 6
A12: Type | B12: Select
A13: Date Issued | B13: =TODAY() -> 46222
A14: Required by
A16: Special 1 | D16: Page 1 | E16: Page 2 | F16: Page 3 | G16: Page 4 | H16: Page 5 | I16: Page 6 | J16: Page 7 | K16: Page 8 | L16: Page 9 | M16: Page 10 | N16: Page 11 | O16: Page 12 | P16: Page 13 | Q16: Page 14 | R16: Page 15 | S16: Page 16 | T16: Page 17 | U16: Page 18 | V16: Page 19 | W16: Page 20 | X16: Page 1 | Y16: Page 2 | Z16: Page 3 | AA16: Page 4 | AB16: Select | AC16: Select | AD16: Select | AE16: Select | AF16: Select | AG16: Select
A17: Special 2 | D17: Single | E17: Single | F17: Single | G17: Single | H17: Single | I17: Single | J17: Single | K17: Single | L17: Single | M17: Single | N17: Single | O17: Single | P17: Single | Q17: Single | R17: Single | S17: Single | T17: Single | U17: Single | V17: Single | W17: Single | X17: Multi | Y17: Multi | Z17: Multi | AA17: Multi | AB17: Select | AC17: Select | AD17: Select | AE17: Select | AF17: Select | AG17: Select
A18: Special 3 | D18: Curtain 1 | E18: Curtain 2 | F18: Curtain 3 | G18: Curtain 4 | H18: Curtain 5 | I18: Curtain 6 | J18: Curtain 7 | K18: Curtain 8 | L18: Curtain 9 | M18: Curtain 10 | N18: Curtain 11 | O18: Curtain 12 | P18: Curtain 13 | Q18: Curtain 14 | R18: Curtain 15 | S18: Curtain 16 | T18: Curtain 17 | U18: Curtain 18 | V18: Curtain 19 | W18: Curtain 20 | X18: Curtain 1 | Y18: Curtain 2 | Z18: Curtain 3 | AA18: Curtain 4 | AB18: Curtain 5 | AC18: Curtain 6 | AD18: Curtain 7 | AE18: Curtain 8 | AF18: Curtain 9 | AG18: Curtain 10
C19: Location / REF | D19: 1 | E19: 1 | F19: 1 | G19: 1 | H19: 1 | X19: 1 | Y19: 1
A20: DROP DOWN LIST | C20: EN1634-1 / EN12101 | D20: Select | E20: EN1634-2 | F20: EN1634-3 | G20: EN1634-4 | H20: EN1634-5 | I20: Select | J20: Select | K20: Select | L20: Select | M20: Select | N20: Select | O20: Select | P20: Select | Q20: Select | R20: Select | S20: Select | T20: Select | U20: Select | V20: Select | W20: Select | X20: EN1634-1 | Y20: EN1634-2 | Z20: Select | AA20: Select | AB20: Select | AC20: Select | AD20: Select | AE20: Select | AF20: Select | AG20: Select
C21: Fire or Smoke | D21: Select | E21: Fire Curtain | F21: Fire Curtain | G21: Fire Curtain | H21: Fire Curtain | I21: Select | J21: Select | K21: Select | L21: Select | M21: Select | N21: Select | O21: Select | P21: Select | Q21: Select | R21: Select | S21: Select | T21: Select | U21: Select | V21: Select | W21: Select | X21: Fire Curtain | Y21: Fire Curtain | Z21: Select | AA21: Select | AB21: Select | AC21: Select | AD21: Select | AE21: Select | AF21: Select | AG21: Select
C22: OverLap Per Barrel | D22: Select | E22: N/A | F22: N/A | G22: N/A | H22: N/A | I22: Select | J22: Select | K22: Select | L22: Select | M22: Select | N22: Select | O22: Select | P22: Select | Q22: Select | R22: Select | S22: Select | T22: Select | U22: Select | V22: Select | W22: Select | X22: 1000 | Y22: 1001 | Z22: Select | AA22: Select | AB22: Select | AC22: Select | AD22: Select | AE22: Select | AF22: Select | AG22: Select
C23: Fixing Type | D23: Select | E23: In Fit | F23: In Fit | G23: In Fit | H23: In Fit | I23: Select | J23: Select | K23: Select | L23: Select | M23: Select | N23: Select | O23: Select | P23: Select | Q23: Select | R23: Select | S23: Select | T23: Select | U23: Select | V23: Select | W23: Select | X23: Face Fit | Y23: Face Fit | Z23: Select | AA23: Select | AB23: Select | AC23: Select | AD23: Select | AE23: Select | AF23: Select | AG23: Select
B24: Total No. Systems | C24: 0
C25: Fabric Type | D25: Select | E25: Select | F25: Select | G25: Select | H25: Select | I25: Select | J25: Select | K25: Select | L25: Select | M25: Select | N25: Select | O25: Select | P25: Select | Q25: Select | R25: Select | S25: Select | T25: Select | U25: Select | V25: Select | W25: Select | X25: Select | Y25: Select | Z25: Select | AA25: Select | AB25: Select | AC25: Select | AD25: Select | AE25: Select | AF25: Select | AG25: Select
C26: Width (mm) | X26: 10000 | Y26: 11000
C27: Height (mm) | X27: 5000 | Y27: 5000
C28: End Plate (10mm Lead In | D28: Select | E28: Select | F28: Select | G28: Select | H28: Select | I28: Select | J28: Select | K28: Select | L28: Select | M28: Select | N28: Select | O28: Select | P28: Select | Q28: Select | R28: Select | S28: Select | T28: Select | U28: Select | V28: Select | W28: Select | X28: 400 | Y28: 400 | Z28: Select | AA28: Select | AB28: Select | AC28: Select | AD28: Select | AE28: Select | AF28: Select | AG28: Select
C29: Side Guides + 8mm | D29: Standard | E29: Standard | F29: Standard | G29: Standard | H29: Standard | I29: Standard | J29: Standard | K29: Standard | L29: Standard | M29: Standard | N29: Standard | O29: Standard | P29: Standard | Q29: Standard | R29: Standard | S29: Standard | T29: Standard | U29: Standard | V29: Standard | W29: Standard | X29: Standard | Y29: Standard | Z29: Standard | AA29: Standard | AB29: Standard | AC29: Standard | AD29: Standard | AE29: Standard | AF29: Standard | AG29: Standard
C30: Bottom Rail Cover | D30: Square | E30: Square | F30: Square | G30: Square | H30: Square | I30: Square | J30: Square | K30: Square | L30: Square | M30: Square | N30: Square | O30: Square | P30: Square | Q30: Square | R30: Square | S30: Square | T30: Square | U30: Square | V30: Square | W30: Square | X30: Square | Y30: Square | Z30: Square | AA30: Square | AB30: Square | AC30: Square | AD30: Square | AE30: Square | AF30: Square | AG30: Square
C31: Bottom Rail Flat Strip | D31: 20x3mm | E31: 20x3mm | F31: 20x3mm | G31: 20x3mm | H31: 20x3mm | I31: 20x3mm | J31: 20x3mm | K31: 20x3mm | L31: 20x3mm | M31: 20x3mm | N31: 20x3mm | O31: 20x3mm | P31: 20x3mm | Q31: 20x3mm | R31: 20x3mm | S31: 20x3mm | T31: 20x3mm | U31: 20x3mm | V31: 20x3mm | W31: 20x3mm | X31: 20x3mm | Y31: 20x3mm | Z31: 20x3mm | AA31: 20x3mm | AB31: 20x3mm | AC31: 20x3mm | AD31: 20x3mm | AE31: 20x3mm | AF31: 20x3mm | AG31: 20x3mm
C32: Barrel - 101mm No. Of Barrel = No of Panels | D32: 1 | E32: 1 | F32: 1 | G32: 1 | H32: 1 | I32: 1 | J32: 1 | K32: 1 | L32: 1 | M32: 1 | N32: 1 | O32: 1 | P32: 1 | Q32: 1 | R32: 1 | S32: 1 | T32: 1 | U32: 1 | V32: 1 | W32: 1 | X32: 2 | Y32: 2 | Z32: Select | AA32: Select | AB32: Select | AC32: Select | AD32: Select | AE32: Select | AF32: Select | AG32: Select
C33: Barrel Flat Strip | D33: 16 x 3mm | E33: 16 x 3mm | F33: 16 x 3mm | G33: 16 x 3mm | H33: 16 x 3mm | I33: 16 x 3mm | J33: 16 x 3mm | K33: 16 x 3mm | L33: 16 x 3mm | M33: 16 x 3mm | N33: 16 x 3mm | O33: 16 x 3mm | P33: 16 x 3mm | Q33: 16 x 3mm | R33: 16 x 3mm | S33: 16 x 3mm | T33: 16 x 3mm | U33: 16 x 3mm | V33: 16 x 3mm | W33: 16 x 3mm | X33: 16 x 3mm | Y33: 16 x 3mm | Z33: 16 x 3mm | AA33: 16 x 3mm | AB33: 16 x 3mm | AC33: 16 x 3mm | AD33: 16 x 3mm | AE33: 16 x 3mm | AF33: 16 x 3mm | AG33: 16 x 3mm
C34: Motor (S or L) | D34: Select | E34: Select | F34: Select | G34: Select | H34: Select | I34: Select | J34: Select | K34: Select | L34: Select | M34: Select | N34: Select | O34: Select | P34: Select | Q34: Select | R34: Select | S34: Select | T34: Select | U34: Select | V34: Select | W34: Select | X34: Dunker (L) | Y34: Dunker (L) | Z34: Select | AA34: Select | AB34: Select | AC34: Select | AD34: Select | AE34: Select | AF34: Select | AG34: Select
C35: Control Panel | D35: CSV x1 | E35: CSV x1 | F35: CSV x1 | G35: CSV x1 | H35: CSV x1 | I35: CSV x1 | J35: CSV x1 | K35: CSV x1 | L35: CSV x1 | M35: CSV x1 | N35: CSV x1 | O35: CSV x1 | P35: CSV x1 | Q35: CSV x1 | R35: CSV x1 | S35: CSV x1 | T35: CSV x1 | U35: CSV x1 | V35: CSV x1 | W35: CSV x2 | X35: CSV x 2 | Y35: CSV x 2 | Z35: CSV x 2 | AA35: CSV x 2 | AB35: CSV x 2 | AC35: CSV x 2 | AD35: CSV x 2 | AE35: CSV x 2 | AF35: CSV x 2 | AG35: CSV x 2
C36: Motor Side | D36: Select | E36: Select | F36: Select | G36: Select | H36: Select | I36: Select | J36: Select | K36: Select | L36: Select | M36: Select | N36: Select | O36: Select | P36: Select | Q36: Select | R36: Select | S36: Select | T36: Select | U36: Select | V36: Select | W36: Select | X36: Right | Y36: Right | Z36: Select | AA36: Select | AB36: Select | AC36: Select | AD36: Select | AE36: Select | AF36: Select | AG36: Select
B37: RAL Colour | C37: Top Box | E37: RAL 9010 | F37: RAL 9010 | G37: RAL 9010 | H37: RAL 9010 | I37: RAL 9010 | J37: RAL 9010 | K37: RAL 9010 | L37: RAL 9010 | M37: RAL 9010 | N37: RAL 9010 | O37: RAL 9010 | P37: RAL 9010 | Q37: RAL 9010 | R37: RAL 9010 | S37: RAL 9010 | T37: RAL 9010 | U37: RAL 9010 | V37: RAL 9010 | W37: RAL 9010 | X37: RAL 9010 | Y37: RAL 9010 | Z37: RAL 9010 | AA37: RAL 9010 | AB37: RAL 9010 | AC37: RAL 9010 | AD37: RAL 9010 | AE37: RAL 9010 | AF37: RAL 9010 | AG37: RAL 9010
C38: End Plate | E38: RAL 9010 | F38: RAL 9010 | G38: RAL 9010 | H38: RAL 9010 | I38: RAL 9010 | J38: RAL 9010 | K38: RAL 9010 | L38: RAL 9010 | M38: RAL 9010 | N38: RAL 9010 | O38: RAL 9010 | P38: RAL 9010 | Q38: RAL 9010 | R38: RAL 9010 | S38: RAL 9010 | T38: RAL 9010 | U38: RAL 9010 | V38: RAL 9010 | W38: RAL 9010 | X38: RAL 9010 | Y38: RAL 9010 | Z38: RAL 9010 | AA38: RAL 9010 | AB38: RAL 9010 | AC38: RAL 9010 | AD38: RAL 9010 | AE38: RAL 9010 | AF38: RAL 9010 | AG38: RAL 9010
C39: Side Guides | E39: RAL 9010 | F39: RAL 9010 | G39: RAL 9010 | H39: RAL 9010 | I39: RAL 9010 | J39: RAL 9010 | K39: RAL 9010 | L39: RAL 9010 | M39: RAL 9010 | N39: RAL 9010 | O39: RAL 9010 | P39: RAL 9010 | Q39: RAL 9010 | R39: RAL 9010 | S39: RAL 9010 | T39: RAL 9010 | U39: RAL 9010 | V39: RAL 9010 | W39: RAL 9010 | X39: RAL 9010 | Y39: RAL 9010 | Z39: RAL 9010 | AA39: RAL 9010 | AB39: RAL 9010 | AC39: RAL 9010 | AD39: RAL 9010 | AE39: RAL 9010 | AF39: RAL 9010 | AG39: RAL 9010
C40: Bottom Rail | E40: RAL 9010 | F40: RAL 9010 | G40: RAL 9010 | H40: RAL 9010 | I40: RAL 9010 | J40: RAL 9010 | K40: RAL 9010 | L40: RAL 9010 | M40: RAL 9010 | N40: RAL 9010 | O40: RAL 9010 | P40: RAL 9010 | Q40: RAL 9010 | R40: RAL 9010 | S40: RAL 9010 | T40: RAL 9010 | U40: RAL 9010 | V40: RAL 9010 | W40: RAL 9010 | X40: RAL 9010 | Y40: RAL 9010 | Z40: RAL 9010 | AA40: RAL 9010 | AB40: RAL 9010 | AC40: RAL 9010 | AD40: RAL 9010 | AE40: RAL 9010 | AF40: RAL 9010 | AG40: RAL 9010
C41: Landing Plate | D41: No | E41: No | F41: No | G41: No | H41: No | I41: Select | J41: Select | K41: Select | L41: Select | M41: Select | N41: Select | O41: Select | P41: Select | Q41: Select | R41: Select | S41: Select | T41: Select | U41: Select | V41: Select | W41: Select | X41: No | Y41: Select | Z41: Select | AA41: Select | AB41: Select | AC41: Select | AD41: Select | AE41: Select | AF41: Select | AG41: Select
C42: No. Key Switch | D42: 1 | E42: 1 | F42: 1 | G42: 1 | H42: 1 | I42: 1 | J42: 1 | K42: 1 | L42: 1 | M42: 1 | N42: 1 | O42: 1 | P42: 1 | Q42: 1 | R42: 1 | S42: 1 | T42: 1 | U42: 1 | V42: 1 | W42: 1 | X42: 1 | Y42: 1 | Z42: 1 | AA42: 1 | AB42: 1 | AC42: 1 | AD42: 1 | AE42: 1 | AF42: 1 | AG42: 1
C43: No. ERB's | D43: 0 | E43: 0 | F43: 0 | G43: 0 | H43: 0 | I43: 0 | J43: 0 | K43: 0 | L43: 0 | M43: 0 | N43: 0 | O43: 0 | P43: 0 | Q43: 0 | R43: 0 | S43: 0 | T43: 0 | U43: 0 | V43: 0 | W43: 0 | X43: 0 | Y43: 0 | Z43: 0 | AA43: 0 | AB43: 0 | AC43: 0 | AD43: 0 | AE43: 0 | AF43: 0 | AG43: 0
C44: Bat. & Main Monitor | D44: 0 | E44: 0 | F44: 0 | G44: 0 | H44: 0 | I44: 0 | J44: 0 | K44: 0 | L44: 0 | M44: 0 | N44: 0 | O44: 0 | P44: 0 | Q44: 0 | R44: 0 | S44: 0 | T44: 0 | U44: 0 | V44: 0 | W44: 0 | X44: 0 | Y44: 0 | Z44: 0 | AA44: 0 | AB44: 0 | AC44: 0 | AD44: 0 | AE44: 0 | AF44: 0 | AG44: 0
...

Sheet Single OUTPUT
A1: Date Issued | C1: ='Data INPUT'!$B$13 -> 46222 | G1: Required by | J1: ='Data INPUT'!$B$14 | M1: Page 1
A2: Client's Name | C2: ='Data INPUT'!$B$4 | J2: ='Data INPUT'!D19 -> 1 | O2: Component | P2: Your Rule - Single Barrel
A3: Order Ref no. | C3: ='Data INPUT'!$B$2 | J3: ='Data INPUT'!D24 | O3: Headbox Length | P3: Same as Overall Width
A4: Project Name | C4: ='Data INPUT'!$B$3 | J4: ='Data INPUT'!D18 -> Curtain 1 | O4: Height | P4: Same as Overall Height
A5: ='Data INPUT'!D21 -> Select | B5: ='Data INPUT'!D25 -> Select | D5: ='Data INPUT'!D20 -> Select | G5: Address : | O5: Endplate | P5: Endplate Size (from input)
G6: ='Data INPUT'!$B$7 | O6: Sideguides | P6: Overall Height minus Endplate Size plus 10
A7: Supply only / Install | C7: ='Data INPUT'!$B$12 -> Select | G7: ='Data INPUT'!$B$8 | O7: Barrel | P7: 180mm shorter than Overall Width
A8: Face Fit / In Fit | C8: ='Data INPUT'!D23 -> Select | G8: ='Data INPUT'!$B$9 | O8: Fabric Width | P8: 100mm shorter than Headbox
A9: Number of Curtain | C9: 1 | G9: ='Data INPUT'!$B$10 | O9: Fabric Height | P9: Overall Height plus 300
G10: Contact Name : | J10: ='Data INPUT'!$B$5 | O10: Bottom Rail | P10: Overall Width - 230mm
G11: Contact Number : | J11: ='Data INPUT'!$B$6
A12: Special | C12: ='Data INPUT'!$B$16 | O12: End Plates Single Barrel
C13: ='Data INPUT'!$B$17 | O13: 160 x 160
C14: ='Data INPUT'!$B$18 | O14: 180 x 180
A15: Size (All Dim is mm) | C15: Width | E15: Height | H15: Note: SINGLE BARREL | O15: 200 x 200
A16: Overall Size | C16: ='Data INPUT'!D26 | D16: x | E16: ='Data INPUT'!D27 | O16: 225 x 225
A17: Headbox | B17: =D18 -> Select | C17: =C16 | H17: 10mm Headbox throat
A18: Endplate | B18: =D18 -> Select | D18: ='Data INPUT'!D28 -> Select
A19: Sideguides | B19: ='Data INPUT'!D29 -> Standard | C19: =E16-B17+10 -> #VALUE! | D19: x | E19: 100 | F19: x | G19: 53
A20: Top Flat Bar | B20: 16mm x 3mm | C20: =C21 -> #VALUE! | D20: x | E20: 1 | H20: 180mm shorter than Headbox
A21: Barrel | C21: =C16-180 -> #VALUE! | D21: x | E21: 1
A22: Bottom Rail Cover 2mm | C22: =C16-230 -> #VALUE! | H22: Rail Fitted by :
A23: Bottom Bar Flat Strip x 25mm | C23: =C24 -> #VALUE!
A24: Curtain | C24: =C16-100 -> #VALUE! | D24: x | E24: =E16+300 -> #VALUE! | H24: Lot Number
C25: With Tabs | H25: Hung by :
A26: Weight curtain + B/R | D26: + | F26: = | H26: Material length + | K26: 300 | L26: mm
A27: Motor | C27: ='Data INPUT'!D34 -> Select | H27: Ref no.
A28: Motor Side | C28: ='Data INPUT'!D36 -> Select
A29: Control Panel | C29: ='Data INPUT'!D35 -> CSV x1 | H29: Ref no.
A30: RAL Colour ALL STEEL | H30: Keyed alike Key Switch | L30: ='Data INPUT'!D42 -> 1
A31: Top Box | C31: ='Data INPUT'!D37 | H31: Emergency Retract Button | L31: ='Data INPUT'!D43 -> 0
A32: Endplate + Bracket | C32: ='Data INPUT'!D38 | H32: Battery & Main Monitor | L32: ='Data INPUT'!D44 -> 0
A33: Sideguides | C33: ='Data INPUT'!D40 | H33: Beam Sensor | L33: ='Data INPUT'!D45 -> 0
A34: Bottom Rail | C34: ='Data INPUT'!#REF! -> #REF! | H34: Audio Visual Sensor | L34: ='Data INPUT'!D46 -> 0
A35: Landing Plate | C35: ='Data INPUT'!D41 -> No | H35: Timer Relay | L35: ='Data INPUT'!D47 -> 0
A36: Additional Parts | F36: Required | H36: Delay / Split Drop | L36: ='Data INPUT'!D48 -> 0
A37: Endplate Guide Bracket
A38: Top Box Support Bracket (approx.600mm each)
A39: Top Box Support Bracket (400mm from edge)
A40: QUALITY CONTROL CHECK | C40: Date
...

Sheet Multiple OUTPUT
A1: Date Issued | C1: ='Data INPUT'!$B$13 -> 46222 | G1: Required by | J1: ='Data INPUT'!$B$14 | M1: Page 1
A2: Client's Name | C2: ='Data INPUT'!$B$4 | J2: ='Data INPUT'!X19 -> 1 | O2: Component | P2: Your Rule - Double Barrel | Q2: Motor Postions
A3: Order Ref no. | C3: ='Data INPUT'!$B$2 | J3: ='Data INPUT'!X24 | O3: Headbox Length | P3: Same as Overall Width
A4: Project Name | C4: ='Data INPUT'!$B$3 | J4: ='Data INPUT'!X18 -> Curtain 1 | O4: Endplate | P4: Endplate Size (from input)
A5: ='Data INPUT'!D21 -> Select | B5: ='Data INPUT'!D25 -> Select | D5: ='Data INPUT'!D20 -> Select | G5: Address : | O5: Sideguides | P5: Overall Height minus Endplate Size plus 10
A6: Supply only / Install | C6: ='Data INPUT'!$B$12 -> Select | G6: ='Data INPUT'!$B$8 | O6: Fabric and Barrel overlap | P6: 300/ 600/ 1000 = 600 +1200 +2000
A7: Face Fit / In Fit | C7: ='Data INPUT'!D23 -> Select | G7: ='Data INPUT'!$B$9 | O7: Barrel Double | P7: For each Barrel deduct 180mm
A8: Number of Curtain | C8: 1 | G8: ='Data INPUT'!$B$10 | O8: Fabric Width | P8: 100mm shorter than Headbox
G9: Contact Name : | J9: ='Data INPUT'!$B$5 | O9: Fabric Height | P9: Overall Height plus 300
G10: Contact Number : | J10: ='Data INPUT'!$B$6 | O10: Bottom Rail | P10: Overall Width - 230mm
A11: Special | C11: ='Data INPUT'!$B$16
C12: ='Data INPUT'!$B$17
C13: ='Data INPUT'!$B$18 | P13: No. Of Panels
A14: Size (All Dim is mm) | C14: Width | E14: Height | H14: Note : MULTIPLE BARREL | O14: up to 5.5m | P14: CSV x 1
A15: Overall Size | C15: ='Data INPUT'!X26 -> 10000 | D15: x | E15: ='Data INPUT'!X27 -> 5000 | O15: 5.5m to 11m | P15: CSV x 2
A16: Headbox | B16: =E17 -> 200 x 400 | C16: =C15 -> 10000 | H16: 10mm Headbox throat | O16: 12m to 17 | P16: CSV x 3
A17: Endplate | B17: ='Data INPUT'!X28 -> 400 | C17: ='Data INPUT'!X28 -> 400 | E17: 200 x 400 | O17: 17m to 22.5 | P17: CSV x 4
A18: Sideguides | B18: ='Data INPUT'!D29 -> Standard | C18: =E15-C17+10 -> 4610 | D18: x | E18: 100 | F18: x | G18: 53 | O18: 22.5 to 28m | P18: CSV x 5
A19: Top Flat Bar | B19: 16mm x 3mm | C19: =D20 -> 5820 | D19: x | E19: =C20 -> 2 | H19: 180mm shorter than Headbox | O19: up to 30m | P19: CSV x 6
A20: Barrel | B20: x | C20: ='Data INPUT'!X32 -> 2 | D20: =(C15+(2*B24)-360)/2 -> 5820
A21: Bottom Rail Cover 2mm | C21: =C15-230 -> 9770 | H21: Rail Fitted by :
A22: Bottom Bar Flat Strip x 25mm | C22: =C21 -> 9770 | D22: drop dw | O22: End Plates Double Barrel
A23: Curtain | C23: =((C15-100)/2)+B24 -> 5950 | D23: x | E23: =E15+300 -> 5300 | F23: x | G23: =C20 -> 2 | H23: Lot Number | O23: 180 x 360
A24: Overlap | B24: ='Data INPUT'!X22 -> 1000 | C24: With Tabs | H24: Hung by : | O24: 200 x 400
A25: Weight curtain + B/R | D25: + | F25: = | H25: Material length + | K25: 300 | L25: mm
A26: Motor | H26: Ref no.
A27: Motor Side
A28: Control Panel | C28: ='Data INPUT'!X35 -> CSV x 2 | H28: Ref no.
A29: RAL Colour ALL STEEL | H29: Keyed alike Key Switch | L29: ='Data INPUT'!D42 -> 1
A30: Top Box | C30: ='Data INPUT'!D37 | H30: Emergency Retract Button | L30: ='Data INPUT'!D43 -> 0
A31: Endplate + Bracket | C31: ='Data INPUT'!D38 | H31: Battery & Main Monitor | L31: ='Data INPUT'!D44 -> 0
A32: Sideguides | C32: ='Data INPUT'!D40 | H32: Beam Sensor | L32: ='Data INPUT'!D45 -> 0
A33: Bottom Rail | C33: ='Data INPUT'!#REF! -> #REF! | H33: Audio Visual Sensor | L33: ='Data INPUT'!D46 -> 0
A34: Landing Plate | C34: ='Data INPUT'!D41 -> No | H34: Timer Relay | L34: ='Data INPUT'!D47 -> 0
A35: Additional Parts | F35: Required | H35: Delay / Split Drop | L35: ='Data INPUT'!D48 -> 0
A36: Endplate Guide Bracket
A37: Top Box Support Bracket (approx.600mm each)
A38: Top Box Support Bracket (400mm from edge)
A39: QUALITY CONTROL CHECK | C39: Date
A40: Date Issued | C40: ='Data INPUT'!$B$13 -> 46222 | G40: Required by | J40: ='Data INPUT'!$B$14 | M40: Page 2
...

Sheet Weight Rules
A2: Weight rule table
A4: Item | B4: Weight rule to use | C4: Kgs/m
A5: Headbox 180 x 180 | B5: 10 kg per metre | C5: =_xlfn.NUMBERVALUE(_xlfn.TEXTBEFORE(B5, " ", 1), ".", ",") -> 10
A6: Headbox 200 x 200 | B6: 10.4 kg per metre | C6: =_xlfn.NUMBERVALUE(_xlfn.TEXTBEFORE(B6, " ", 1), ".", ",") -> 10.4
A7: Headbox 200 x 400 | B7: 12.4 kg per metre | C7: =_xlfn.NUMBERVALUE(_xlfn.TEXTBEFORE(B7, " ", 1), ".", ",") -> 12.4
A8: Side guides 100mm pair | B8: 12.1 kg per metre height | C8: =_xlfn.NUMBERVALUE(_xlfn.TEXTBEFORE(B8, " ", 1), ".", ",") -> 12.1
A9: Side guides 70mm pair | B9: 10.3 kg per metre height | C9: =_xlfn.NUMBERVALUE(_xlfn.TEXTBEFORE(B9, " ", 1), ".", ",") -> 10.3
A10: Barrel Ø100 | B10: 6 kg per metre width | C10: =_xlfn.NUMBERVALUE(_xlfn.TEXTBEFORE(B10, " ", 1), ".", ",") -> 6
A11: Curtain fabric FS240 | B11: 0.75 kg per m² | C11: =_xlfn.NUMBERVALUE(_xlfn.TEXTBEFORE(B11, " ", 1), ".", ",") -> 0.75
A12: Curtain fabric FS Plus | B12: 2.7 kg per m² | C12: =_xlfn.NUMBERVALUE(_xlfn.TEXTBEFORE(B12, " ", 1), ".", ",") -> 2.7
A13: Bottom rail | B13: 5 kg per metre width | C13: =_xlfn.NUMBERVALUE(_xlfn.TEXTBEFORE(B13, " ", 1), ".", ",") -> 5
A14: CSV small motor | B14: 2.5 kg each | C14: =_xlfn.NUMBERVALUE(_xlfn.TEXTBEFORE(B14, " ", 1), ".", ",") -> 2.5
A15: CSV large motor | B15: 8 kg each | C15: =_xlfn.NUMBERVALUE(_xlfn.TEXTBEFORE(B15, " ", 1), ".", ",") -> 8
A16: CSV XL motor | B16: 9 kg each | C16: =_xlfn.NUMBERVALUE(_xlfn.TEXTBEFORE(B16, " ", 1), ".", ",") -> 9
... A22: Audio visual | B22: 0.3 kg each | C22: =_xlfn.NUMBERVALUE(_xlfn.TEXTBEFORE(B22, " ", 1), ".", ",") -> 0.3
A23: Timer relay kit | B23: old sheet has no weight — use 0.2 kg if you want to allow for it | C23: 0.2
A24: Delay / split drop | B24: usually programming/control logic, so 0 kg, unless a separate kit is supplied | C24: 0
A25: Single endplate pair | B25: 2 kg per pair | C25: =_xlfn.NUMBERVALUE(_xlfn.TEXTBEFORE(B25, " ", 1), ".", ",") -> 2
A26: Multi endplate pair | B26: 4 kg per pair | C26: =_xlfn.NUMBERVALUE(_xlfn.TEXTBEFORE(B26, " ", 1), ".", ",") -> 4
A27: Packing / pallet allowance | B27: add 10% or add pallet separately, normally 20 kg | C27: 20

Sheet Formulas Sheet Multi
A1: Double Barrel / Under-Over Barrel Formula Sheet
A2: Input | B2: Cell | C2: Value | D2: Unit | E2: Notes
A3: Overall Width | B3: B3 | C3: 30000 | D3: mm | E3: Change this to your system width
A4: Overall Height | B4: B4 | C4: 5500 | D4: mm | E4: Change this to your system height
A5: Number of Barrels | B5: B5 | C5: 6 | D5: No. | E5: Double barrel
A6: Fabric Side Deduction | B6: B6 | C6: 100 | D6: mm | E6: 50mm each side = 100mm total
A7: Barrel / Flat Bar Deduction Each | B7: B7 | C7: 180 | D7: mm | E7: Each barrel / top flat bar is 180mm shorter
A8: Material Height Add-On | B8: B8 | C8: 300 | D8: mm | E8: Curtain material length add-on
A9: Side Guide Height Deduction | B9: B9 | C9: 400 | D9: mm | E9: O/H - HB Height + 10mm
A10: Bottom Rail Cover Deduction | B10: B10 | C10: 230 | D10: mm | E10: Overall width - 230
A11: Bottom Bar Tongue Total | B11: B11 | C11: 176 | D11: mm | E11: 88mm each side
A13: Overlap | B13: Curtain Width Each | C13: Curtain Height | D13: Curtain Size | E13: Barrel Each | F13: Top Flat Bar Each | G13: Bottom Bar Flat Strip
A14: 300 | B14: =(($C$3-$C$6)/$C$5)+A14 -> 5283.3333 | C14: =$C$4+$C$8 -> 5800 | D14: =$C$5&" x "&ROUND(B14,0)&" x "&C14 -> 6 x 5283 x 5800 | E14: =($C$3+($C$5*A14)-($C$5*$C$7))/$C$5 -> 5120 | F14: =E14 -> 5120 | G14: =($C$3-$C$10)+$C$11 -> 29946 | H14: SmokeSafe
A15: 600 | B15: =(($C$3-$C$6)/$C$5)+A15 -> 5583.3333 | C15: =$C$4+$C$8 -> 5800 | D15: =$C$5&" x "&ROUND(B15,0)&" x "&C15 -> 6 x 5583 x 5800 | E15: =($C$3+($C$5*A15)-($C$5*$C$7))/$C$5 -> 5420 | F15: =E15 -> 5420 | G15: =($C$3-$C$10)+$C$11 -> 29946 | H15: EN1634-1
A16: 1000 | B16: =(($C$3-$C$6)/$C$5)+A16 -> 5983.3333 | C16: =$C$4+$C$8 -> 5800 | D16: =$C$5&" x "&ROUND(B16,0)&" x "&C16 -> 6 x 5983 x 5800 | E16: =($C$3+($C$5*A16)-($C$5*$C$7))/$C$5 -> 5820 | F16: =E16 -> 5820 | G16: =($C$3-$C$10)+$C$11 -> 29946 | H16: BS8524-1
A18: Copy/Paste Formula Reference
A19: Item | B19: Excel Formula | C19: What it does
A20: Curtain Width Each | B20: =((OverallWidth-100)/2)+Overlap | C20: Uses fabric sitting 50mm into each side guide
A21: Curtain Height | B21: =OverallHeight+300 | C21: Material length / curtain drop allowance
A22: Barrel Each | B22: =(OverallWidth+(2*Overlap)-(2*180))/2 | C22: Overlap added to both barrels, then 180mm deducted from each barrel
A23: Top Flat Bar Each | B23: =(OverallWidth+(2*Overlap)-(2*180))/2 | C23: Same as barrel
A24: Bottom Rail Cover | B24: =OverallWidth-230 | C24: Does not change with overlap
A25: Bottom Bar Flat Strip | B25: =(OverallWidth-230)+176 | C25: Does not change with overlap
A27: Important notes
A28: Curtain formula uses W - 100 because fabric sits 50mm into each side guide.
A29: Barrel / top flat bar formula deducts 180mm per barrel, so 2 barrels = 360mm total deduction.
A30: Change the input values in C3:C11 or Production Sheet B2:B11 and formulas update automatically.

Sheet QCF
A1: Quality Control Form Steel - Fabrication
A2: IFS-QCF-V1-05/07/2026
A3: Client / Project Name: | B3: ='Data INPUT'!B3
A4: Project Order / Quote Ref: | B4: ='Data INPUT'!B2
A5: Start Date:
A6: No. of Systems:
A8: Quality Control Checks against Cutting Sheet:
A9: Check alignments with hole punch slots, check brackets are correctly positioned, check exact sizes match the cutting sheets.
A11: Component Type | B11: Width | C11: Height | D11: Quality OK (tick) | F11: Remedial action | G11: Signed / Name
D12: Yes | E12: No
A13: Headbox:
A14: Back
A15: Front
A16: Headbox sizes
A17: End Plates:
A18: Left
A19: Right
A20: Motor end
A21: Dummy end
A22: End plate Sizes
A23: Side Guides:
A24: Left
... A42: IFS-QCF-V1-05/07/2026
A43: Client / Project Name: | B43: ='Data INPUT'!B3
A44: Order / Quote Ref: | B44: ='Data INPUT'!B2
A45: Start Date:
A47: Quality Control Checks against Cutting Sheet: Manufactured to accurate sizes as per cutting list, fabric quality checking.
A49: Quantity | B49: Component Type | C49: Width | D49: Height | E49: Quality OK? | G49: Remedial action
E50: Yes | F50: No | G50: Signed
A52: Material Type: (Circle)
A53: SmokeSafe Only
A54: FireSafe 120
A55: FireSafe 240
A56: FireSafe Plus Only
A57: Fabric Defects
A59: Tabs Added
A60: Spacings for 100mm barrel or 70mm?
A62: Sewing of each panel in alignment
A64: Satisfied with quality of Stitching?
A68: Quality Control Form – Control Panels
...
